Workbook

Sheet README
A1: Vriddhi — Costing, Pricing & P&L Workbook
A2: Built 25 Sep 2026 from the Vriddhi codebase. All figures are estimates until validated against a real Firebase invoice.
A4: How to use
A5: 1 | B5: Fill the yellow cells on the Inputs sheet (college size, unit prices, per-role usage, events). Grey cells are formulas — do not overwrite.
A6: 2 | B6: Adjust the academic Calendar (days per month by type, fee/admission timing, AI weights).
A7: 3 | B7: Enter your team on 'Team & Overheads' (5 × ₹30,000 is pre-filled), overheads, onboarding out-of-pocket, and how many colleges share the team.
A8: 4 | B8: Review 'AI Costing' — change models (dropdown), calls per year, tokens per call and the safety buffer.
A9: 5 | B9: 'Usage Model' shows reads/writes per role per day type and the monthly grid with the Blaze free quota applied PER DAY.
A10: 6 | B10: 'Monthly Plan' and 'Annual Summary' give the 12-month cash plan and per-student / per-user cost.
A11: 7 | B11: Set your price on 'Pricing & P&L' to see revenue, gross profit, margin, break-even and a 3-year P&L. 'Sensitivity' shows margin by price × colleges.
A12: 8 | B12: 'Build Cost' estimates what it costs to build a product like this (for investor / 'why not build it ourselves' conversations).
A14: Colour legend
A15: Yellow | B15: Input — edit freely
A16: Grey | B16: Formula — recalculates automatically
A17: Green | B17: Key output
A19: Blaze plan reminder | B19: Firestore gives 50,000 reads and 20,000 writes free PER DAY (resets daily, no roll-over), then $0.06 / 100K reads and $0.18 / 100K writes. A 5,000-student college uses ~3.4M reads on a teaching day, so the quota covers ~1.5% — you pay from day one, but the unit prices are tiny.
A20: GST | B20: Cloud prices are ex-GST. Google Cloud India adds 18% GST; set 'GST recoverable' = 1 on Inputs if you claim input credit, else 0 to treat it as a cost. Your invoice to the college carries 18% GST on top of the prices here.
A21: Reconciliation | B21: With the default inputs the sheet reproduces docs/COSTING_PLAN_1YEAR_5000_STUDENTS.md: cloud ₹52,266, AI ₹1,16,020, team ₹18,00,000. The only difference is overheads: the report used a flat ₹15,000 'tools' line; the sheet itemises ₹39,660 (Workspace, domain, ₹30,000 travel), so break-even is ₹402 instead of ₹397 per student.
A22: Source | B22: scripts/firebase-yearly-cost-plan.mjs and docs/COSTING_PLAN_1YEAR_5000_STUDENTS.md in the Vriddhi repository. Regenerate this workbook with: python3 scripts/build-costing-sheet.py

Sheet Inputs
A1: Inputs — every assumption in one place
A2: Yellow = edit. Grey = derived. Units in column D, source/notes in column E.
B5: 1. College & users
B6: Students | C6: 5000 | D6: people | E6: the billing unit
B7: Faculty (teaching staff, incl. HODs & mentors) | C7: =ROUND(Inputs!$C$6/25,0) | D7: people | E7: default 1:25; overwrite with the real number
B8: HODs (extra department pages on top of faculty) | C8: 15 | D8: people
B9: Mentors (extra mentee pages on top of faculty) | C9: 40 | D9: people
B10: Principal / college admin / exam cell users | C10: 5 | D10: people
B11: Accounts team users | C11: 5 | D11: people | E11: fee management, challans, collections, finance reports, vendor bills
B12: Operations team users (office, library, inventory, procurement, admissions) | C12: 8 | D12: people
B13: Superadmin users (your team) | C13: 2 | D13: people
B14: Total accounts (students + college staff) | C14: =Inputs!$C$6+Inputs!$C$7+Inputs!$C$10+Inputs!$C$11+Inputs!$C$12 | D14: people
B15: Students per section | C15: 60 | D15: people
B16: Sections | C16: =ROUNDUP(Inputs!$C$6/Inputs!$C$15,0)
B17: Periods per day with attendance | C17: 5
B18: Attendance sessions per teaching day | C18: =Inputs!$C$16*Inputs!$C$17 | E18: each session = 1 write per student + 3 docs
B19: Final-year students (placement prep, no-dues) | C19: =ROUND(Inputs!$C$6/3,0)
B20: New admissions per year | C20: =ROUND(Inputs!$C$6*0.3,0)
B22: 2. Currency & Firebase Blaze unit prices (Sept 2026 list prices, asia-south1)
B23: Exchange rate | C23: 96 | D23: ₹ per USD
B24: Firestore document reads | C24: 0.06 | D24: $ per 100,000 | E24: free 50,000 per day on Blaze (default database only)
B25: Firestore document writes | C25: 0.18 | D25: $ per 100,000 | E25: free 20,000 per day
B26: Free reads per day | C26: 50000 | E26: resets at midnight US-Pacific; unused quota does not roll over
B27: Free writes per day | C27: 20000
B28: Firestore stored data | C28: 0.18 | D28: $ per GiB-month
B29: Firestore free storage | C29: 1 | D29: GiB
B30: Cloud Storage (files) stored | C30: 0.026 | D30: $ per GB-month
B31: Cloud Storage free storage | C31: 5 | D31: GB
B32: Cloud Storage downloads | C32: 0.12 | D32: $ per GB
B33: Cloud Storage free downloads | C33: 30 | D33: GB per month | E33: 1 GB per day
B34: Firebase Hosting transfer | C34: 0.15 | D34: $ per GB
B35: Hosting free transfer | C35: 10.8 | D35: GB per month | E35: 360 MB per day
B36: Cloud Functions | C36: 0 | D36: $ per month | E36: 2.3M invocations/yr and all compute sit inside the free tier (2M invocations, 180K vCPU-s, 360K GiB-s per month); set >0 if you add minInstances
B37: Fixed monthly items (Artifact Registry, Secret Manager, Realtime DB) | C37: 1.7 | D37: $ per month
B38: GST on Google Cloud bill | C38: 0.18
B39: GST recoverable as input credit? (1 = yes, 0 = treat as cost) | C39: 1
B41: 3. Student usage (per ACTIVE student per day) — from src/modules/student
B42: Active share on teaching days | C42: 0.6
B43: Active share on internal-assessment (online test) days | C43: 0.9
B44: Active share on university exam days | C44: 0.4
...

Sheet Calendar
A1: Academic calendar — days per month by type (Aug → Jul, Karnataka degree college)
A2: Teach = classes with attendance · IA = internal-assessment / online-test days (classes continue) · Uni = university exam days · Result = result publication · Office = office working days with no classes (admissions, vacation) · Off = weekends & holidays. Shares: fee collections / admissions per month must each total 100%. AI weight distributes the annual AI budget.
A3: Month | B3: Teach | C3: IA | D3: Uni | E3: Result | F3: Office | G3: Off | H3: Working days | I3: Total days | J3: Attendance ramp | K3: Fee share | L3: Admission share | M3: Challan burst | N3: Semester rollover | O3: Timetable gen | P3: Hall tickets | Q3: No-dues | R3: AI weight
A4: Aug 2026 | B4: 20 | C4: 0 | D4: 0 | E4: 0 | F4: 2 | G4: 9 | H4: =B4+C4+D4+E4+F4 | I4: =H4+G4 | J4: 0.1 | K4: 0.3 | L4: 0.15 | M4: 1 | N4: 1 | O4: 1 | P4: 0 | Q4: 0 | R4: 0.04
A5: Sep 2026 | B5: 22 | C5: 0 | D5: 0 | E5: 0 | F5: 0 | G5: 8 | H5: =B5+C5+D5+E5+F5 | I5: =H5+G5 | J5: 0.35 | K5: 0.15 | L5: 0.05 | M5: 0 | N5: 0 | O5: 0 | P5: 0 | Q5: 0 | R5: 0.08
A6: Oct 2026 | B6: 15 | C6: 6 | D6: 0 | E6: 0 | F6: 0 | G6: 10 | H6: =B6+C6+D6+E6+F6 | I6: =H6+G6 | J6: 0.6 | K6: 0.05 | L6: 0 | M6: 1 | N6: 0 | O6: 0 | P6: 0 | Q6: 0 | R6: 0.12
A7: Nov 2026 | B7: 16 | C7: 6 | D7: 0 | E7: 0 | F7: 0 | G7: 8 | H7: =B7+C7+D7+E7+F7 | I7: =H7+G7 | J7: 0.85 | K7: 0.02 | L7: 0 | M7: 0 | N7: 0 | O7: 0 | P7: 0 | Q7: 0 | R7: 0.14
A8: Dec 2026 | B8: 10 | C8: 0 | D8: 8 | E8: 0 | F8: 4 | G8: 9 | H8: =B8+C8+D8+E8+F8 | I8: =H8+G8 | J8: 1 | K8: 0.02 | L8: 0 | M8: 0 | N8: 0 | O8: 0 | P8: 1 | Q8: 0 | R8: 0.1
A9: Jan 2027 | B9: 8 | C9: 0 | D9: 9 | E9: 0 | F9: 3 | G9: 11 | H9: =B9+C9+D9+E9+F9 | I9: =H9+G9 | J9: 1 | K9: 0.25 | L9: 0 | M9: 1 | N9: 1 | O9: 1 | P9: 0 | Q9: 0 | R9: 0.05
A10: Feb 2027 | B10: 21 | C10: 0 | D10: 0 | E10: 1 | F10: 0 | G10: 6 | H10: =B10+C10+D10+E10+F10 | I10: =H10+G10 | J10: 1 | K10: 0.15 | L10: 0 | M10: 0 | N10: 0 | O10: 0 | P10: 0 | Q10: 0 | R10: 0.07
A11: Mar 2027 | B11: 15 | C11: 6 | D11: 0 | E11: 0 | F11: 0 | G11: 10 | H11: =B11+C11+D11+E11+F11 | I11: =H11+G11 | J11: 1 | K11: 0.04 | L11: 0 | M11: 1 | N11: 0 | O11: 0 | P11: 0 | Q11: 0 | R11: 0.12
A12: Apr 2027 | B12: 16 | C12: 6 | D12: 0 | E12: 0 | F12: 0 | G12: 8 | H12: =B12+C12+D12+E12+F12 | I12: =H12+G12 | J12: 1 | K12: 0.01 | L12: 0 | M12: 0 | N12: 0 | O12: 0 | P12: 0 | Q12: 0 | R12: 0.14
A13: May 2027 | B13: 8 | C13: 0 | D13: 10 | E13: 0 | F13: 4 | G13: 9 | H13: =B13+C13+D13+E13+F13 | I13: =H13+G13 | J13: 1 | K13: 0.01 | L13: 0 | M13: 0 | N13: 0 | O13: 0 | P13: 1 | Q13: 1 | R13: 0.09
A14: Jun 2027 | B14: 0 | C14: 0 | D14: 5 | E14: 1 | F14: 16 | G14: 8 | H14: =B14+C14+D14+E14+F14 | I14: =H14+G14 | J14: 1 | K14: 0 | L14: 0.4 | M14: 0 | N14: 0 | O14: 0 | P14: 0 | Q14: 0 | R14: 0.03
A15: Jul 2027 | B15: 0 | C15: 0 | D15: 0 | E15: 0 | F15: 23 | G15: 8 | H15: =B15+C15+D15+E15+F15 | I15: =H15+G15 | J15: 1 | K15: 0 | L15: 0.4 | M15: 0 | N15: 0 | O15: 0 | P15: 0 | Q15: 0 | R15: 0.02
A16: TOTAL | B16: =SUM(B4:B15) | C16: =SUM(C4:C15) | D16: =SUM(D4:D15) | E16: =SUM(E4:E15) | F16: =SUM(F4:F15) | G16: =SUM(G4:G15) | H16: =SUM(H4:H15) | I16: =SUM(I4:I15) | K16: =SUM(K4:K15) | L16: =SUM(L4:L15) | R16: =SUM(R4:R15)
I17: ← 365 | K17: ← must be 100% | L17: ← must be 100% | R17: ← must be 100%

Sheet Team & Overheads
A1: Internal team, overheads and onboarding
A2: Gross salaries per month. Labour for onboarding/training is inside these salaries; only out-of-pocket onboarding costs are listed separately.
A3: Role | B3: Count | C3: Gross ₹ / month | D3: Months / year | E3: Annual ₹
A4: Full-stack developer | B4: 1 | C4: 30000 | D4: 12 | E4: =B4*C4*D4
A5: Full-stack developer | B5: 1 | C5: 30000 | D5: 12 | E5: =B5*C5*D5
A6: Support & training executive | B6: 1 | C6: 30000 | D6: 12 | E6: =B6*C6*D6
A7: Support & training executive | B7: 1 | C7: 30000 | D7: 12 | E7: =B7*C7*D7
A8: Project / customer-success lead | B8: 1 | C8: 30000 | D8: 12 | E8: =B8*C8*D8
B9: 0 | C9: 0 | D9: 12 | E9: =B9*C9*D9
B10: 0 | C10: 0 | D10: 12 | E10: =B10*C10*D10
B11: 0 | C11: 0 | D11: 12 | E11: =B11*C11*D11
B12: 0 | C12: 0 | D12: 12 | E12: =B12*C12*D12
B13: 0 | C13: 0 | D13: 12 | E13: =B13*C13*D13
A14: Total team cost per year | E14: =SUM(E4:E13)
A15: Total team cost per month | E15: =E14/12
A17: Colleges sharing this team (allocation divisor) | E17: 1
A18: Team cost allocated to THIS college per year | E18: =E14/E17
A21: Overhead item (per year) | B21: Annual ₹ | C21: Shared across colleges? (1 = yes, 0 = this college only) | D21: Allocated to this college ₹
A22: Google Workspace (5 seats) | B22: 8160 | C22: 1 | D22: =IF(C22=1,B22/'Team & Overheads'!$E$17,B22)
A23: Domain + DNS | B23: 1500 | C23: 1 | D23: =IF(C23=1,B23/'Team & Overheads'!$E$17,B23)
A24: Error monitoring (Sentry) — optional | B24: 0 | C24: 1 | D24: =IF(C24=1,B24/'Team & Overheads'!$E$17,B24)
A25: AI coding tools for developers — optional | B25: 0 | C25: 1 | D25: =IF(C25=1,B25/'Team & Overheads'!$E$17,B25)
A26: Travel / site visits to the college | B26: 30000 | C26: 0 | D26: =IF(C26=1,B26/'Team & Overheads'!$E$17,B26)
A27: Laptops, internet, phones (amortised) | B27: 0 | C27: 1 | D27: =IF(C27=1,B27/'Team & Overheads'!$E$17,B27)
A28: Google Cloud Standard support — optional | B28: 0 | C28: 1 | D28: =IF(C28=1,B28/'Team & Overheads'!$E$17,B28)
A29: WhatsApp / SMS gateway — optional add-on | B29: 0 | C29: 0 | D29: =IF(C29=1,B29/'Team & Overheads'!$E$17,B29)
B30: 0 | C30: 1 | D30: =IF(C30=1,B30/'Team & Overheads'!$E$17,B30)
B31: 0 | C31: 1 | D31: =IF(C31=1,B31/'Team & Overheads'!$E$17,B31)
A32: Total overheads allocated to this college per year | D32: =SUM(D22:D31)
A33: Shared overheads (total, before allocation) | D33: =SUMIF(C22:C31,1,B22:B31)
A34: Per-college overheads (this college only) | D34: =SUMIF(C22:C31,0,B22:B31)
A37: Onboarding out-of-pocket (year 1, this college) | B37: ₹
A38: Travel & stay during go-live weeks | B38: 20000
A39: Training material & printing | B39: 10000
A40: Data-migration contractor / data entry — optional | B40: 0
B41: 0
B42: 0
A43: Total onboarding out-of-pocket | B43: =SUM(B38:B42)

Sheet AI Costing
A1: AI / LLM costing by feature
A2: Prices per 1M tokens (Sept 2026). gemini-1.5-flash was shut down 29 Sep 2025 — chat / prep / study packs must move to gemini-2.5-flash-lite (cheaper) or gemini-2.5-flash. Pick the model per feature from the dropdown.
A3: Model | B3: $ per 1M input tokens | C3: $ per 1M output tokens
A4: gemini-2.5-flash | B4: 0.3 | C4: 2.5
A5: gemini-2.5-flash-lite | B5: 0.1 | C5: 0.4
A6: gpt-4o-mini | B6: 0.15 | C6: 0.6
A7: deepseek-chat | B7: 0.28 | C7: 0.42
A8: custom-model-1 | B8: 0 | C8: 0
A9: custom-model-2 | B9: 0 | C9: 0
A12: Feature | B12: Model | C12: Calls per year | D12: Tokens in / call | E12: Tokens out / call | F12: $ per call | G12: ₹ per call | H12: $ per year | I12: ₹ per year | J12: Code path & cost guard
A13: AI question generation (faculty) | B13: gemini-2.5-flash | C13: =Inputs!$C$7*30 | D13: 2500 | E13: 4000 | F13: =(D13*VLOOKUP(B13,$A$4:$C$9,2,FALSE)+E13*VLOOKUP(B13,$A$4:$C$9,3,FALSE))/1000000 | G13: =F13*Inputs!$C$23 | H13: =C13*F13 | I13: =H13*Inputs!$C$23 | J13: routes/ai-questions.ts — TIER_CONFIG 100/500/1000 questions per day
A14: AI paper parsing (Gemini fallback) | B14: gemini-2.5-flash | C14: =Inputs!$C$7*6*0.4 | D14: 10000 | E14: 5000 | F14: =(D14*VLOOKUP(B14,$A$4:$C$9,2,FALSE)+E14*VLOOKUP(B14,$A$4:$C$9,3,FALSE))/1000000 | G14: =F14*Inputs!$C$23 | H14: =C14*F14 | I14: =H14*Inputs!$C$23 | J14: paperParsing.ts — deterministic parser first
A15: AI grading suggestions (descriptive answers) | B15: gemini-2.5-flash | C15: =Inputs!$C$6*Inputs!$C$89*0.3 | D15: 8000 | E15: 2000 | F15: =(D15*VLOOKUP(B15,$A$4:$C$9,2,FALSE)+E15*VLOOKUP(B15,$A$4:$C$9,3,FALSE))/1000000 | G15: =F15*Inputs!$C$23 | H15: =C15*F15 | I15: =H15*Inputs!$C$23 | J15: studentAssessments.ts — cached per attempt, ≤ 50 questions
A16: AI study-material packs (cached, shared) | B16: gemini-2.5-flash | C16: 12000 | D16: 3000 | E16: 5000 | F16: =(D16*VLOOKUP(B16,$A$4:$C$9,2,FALSE)+E16*VLOOKUP(B16,$A$4:$C$9,3,FALSE))/1000000 | G16: =F16*Inputs!$C$23 | H16: =C16*F16 | I16: =H16*Inputs!$C$23 | J16: routes/ai-chat.ts /study-material — cache + 5/day/student + 400/day/college
A17: AI study assistant chat (students) | B17: gemini-2.5-flash | C17: =Inputs!$C$6*0.3*150 | D17: 3000 | E17: 500 | F17: =(D17*VLOOKUP(B17,$A$4:$C$9,2,FALSE)+E17*VLOOKUP(B17,$A$4:$C$9,3,FALSE))/1000000 | G17: =F17*Inputs!$C$23 | H17: =C17*F17 | I17: =H17*Inputs!$C$23 | J17: routes/ai-chat.ts /chat — NO per-student daily cap yet; add 20/day
A18: Placement prep generation (final years) | B18: gemini-2.5-flash | C18: =Inputs!$C$19*20 | D18: 2000 | E18: 3000 | F18: =(D18*VLOOKUP(B18,$A$4:$C$9,2,FALSE)+E18*VLOOKUP(B18,$A$4:$C$9,3,FALSE))/1000000 | G18: =F18*Inputs!$C$23 | H18: =C18*F18 | I18: =H18*Inputs!$C$23 | J18: routes/prep.ts — rate limiter only
B19: gemini-2.5-flash-lite | C19: 0 | D19: 0 | E19: 0 | F19: =(D19*VLOOKUP(B19,$A$4:$C$9,2,FALSE)+E19*VLOOKUP(B19,$A$4:$C$9,3,FALSE))/1000000 | G19: =F19*Inputs!$C$23 | H19: =C19*F19 | I19: =H19*Inputs!$C$23
B20: gemini-2.5-flash-lite | C20: 0 | D20: 0 | E20: 0 | F20: =(D20*VLOOKUP(B20,$A$4:$C$9,2,FALSE)+E20*VLOOKUP(B20,$A$4:$C$9,3,FALSE))/1000000 | G20: =F20*Inputs!$C$23 | H20: =C20*F20 | I20: =H20*Inputs!$C$23
A21: AI cost per year — base estimate | I21: =SUM(I13:I20)
A22: Safety buffer on AI (1.0 = none; raise to 1.5–2.0 if you do not add the per-student chat cap). P&L adds its own contingency. | I22: 1
A23: AI BUDGET per year used in the plan | I23: =I21*I22
A24: AI budget per student per year | I24: =I23/Inputs!$C$6

Sheet Usage Model
A1: Usage model — Firestore reads & writes per role per day type, then month by month
A2: Part A is the steady-state daily profile (attendance ramp = 1). Part B applies the calendar, the per-month attendance ramp, fee/admission timing and one-off bursts, and charges only the reads/writes above the daily free quota.
A3: A. Daily reads & writes by day type (steady state) | B3: READS per day | I3: WRITES per day
A4: Component | B4: Teach | C4: IA | D4: Uni | E4: Result | F4: Office | G4: Off | I4: Teach | J4: IA | K4: Uni | L4: Result | M4: Office | N4: Off
A5: Students | B5: =Inputs!$C$6*Inputs!$C$42*(Inputs!$C$47*(Inputs!$C$49+Inputs!$C$50)+Inputs!$C$51) | C5: =Inputs!$C$6*Inputs!$C$43*(Inputs!$C$47*(Inputs!$C$49+Inputs!$C$50)+Inputs!$C$51) | D5: =Inputs!$C$6*Inputs!$C$44*(Inputs!$C$48*(Inputs!$C$49+Inputs!$C$50)+Inputs!$C$52) | E5: =Inputs!$C$6*Inputs!$C$45*(Inputs!$C$48*(Inputs!$C$49+Inputs!$C$50)+Inputs!$C$53) | F5: =Inputs!$C$6*Inputs!$C$46*(Inputs!$C$48*(Inputs!$C$49+Inputs!$C$50)+Inputs!$C$53) | G5: =Inputs!$C$6*Inputs!$C$46*(Inputs!$C$48*(Inputs!$C$49+Inputs!$C$50)+Inputs!$C$53) | I5: =Inputs!$C$6*Inputs!$C$42*Inputs!$C$54 | J5: =Inputs!$C$6*Inputs!$C$43*Inputs!$C$54 | K5: =Inputs!$C$6*Inputs!$C$44*Inputs!$C$55 | L5: =Inputs!$C$6*Inputs!$C$45*Inputs!$C$55 | M5: =Inputs!$C$6*Inputs!$C$46*Inputs!$C$55 | N5: =Inputs!$C$6*Inputs!$C$46*Inputs!$C$55
A6: Faculty | B6: =Inputs!$C$7*Inputs!$C$59*Inputs!$C$62 | C6: =Inputs!$C$7*Inputs!$C$59*(Inputs!$C$62+Inputs!$C$64) | D6: =Inputs!$C$7*Inputs!$C$60*Inputs!$C$66 | E6: =Inputs!$C$7*Inputs!$C$61*Inputs!$C$68 | F6: =Inputs!$C$7*Inputs!$C$61*Inputs!$C$68 | G6: =Inputs!$C$7*Inputs!$C$61*Inputs!$C$68 | I6: =Inputs!$C$7*Inputs!$C$59*Inputs!$C$63 | J6: =Inputs!$C$7*Inputs!$C$59*(Inputs!$C$63+Inputs!$C$65) | K6: =Inputs!$C$7*Inputs!$C$60*Inputs!$C$67 | L6: =Inputs!$C$7*Inputs!$C$61*Inputs!$C$69 | M6: =Inputs!$C$7*Inputs!$C$61*Inputs!$C$69 | N6: =Inputs!$C$7*Inputs!$C$61*Inputs!$C$69
A7: HOD extra | B7: =Inputs!$C$8*Inputs!$C$70 | C7: =Inputs!$C$8*Inputs!$C$70 | D7: =0 | E7: =0 | F7: =0 | G7: =0 | I7: =Inputs!$C$8*Inputs!$C$71 | J7: =Inputs!$C$8*Inputs!$C$71 | K7: =0 | L7: =0 | M7: =0 | N7: =0
A8: Mentor extra | B8: =Inputs!$C$9*Inputs!$C$72 | C8: =Inputs!$C$9*Inputs!$C$72 | D8: =0 | E8: =0 | F8: =0 | G8: =0 | I8: =Inputs!$C$9*Inputs!$C$73 | J8: =Inputs!$C$9*Inputs!$C$73 | K8: =0 | L8: =0 | M8: =0 | N8: =0
A9: Attendance marking (sessions) | B9: =Inputs!$C$18*Inputs!$C$74 | C9: =Inputs!$C$18*Inputs!$C$76*Inputs!$C$74 | D9: =0 | E9: =0 | F9: =0 | G9: =0 | I9: =Inputs!$C$18*Inputs!$C$75 | J9: =Inputs!$C$18*Inputs!$C$76*Inputs!$C$75 | K9: =0 | L9: =0 | M9: =0 | N9: =0
A10: Principal / admin / exam cell | B10: =Inputs!$C$10*Inputs!$C$77 | C10: =Inputs!$C$10*Inputs!$C$77 | D10: =Inputs!$C$10*Inputs!$C$77 | E10: =Inputs!$C$10*Inputs!$C$77 | F10: =Inputs!$C$10*Inputs!$C$77 | G10: =Inputs!$C$10*Inputs!$C$77*Inputs!$C$86 | I10: =Inputs!$C$10*Inputs!$C$78 | J10: =Inputs!$C$10*Inputs!$C$78 | K10: =Inputs!$C$10*Inputs!$C$78 | L10: =Inputs!$C$10*Inputs!$C$78 | M10: =Inputs!$C$10*Inputs!$C$78 | N10: =Inputs!$C$10*Inputs!$C$78*Inputs!$C$86
A11: Accounts team | B11: =Inputs!$C$11*Inputs!$C$79 | C11: =Inputs!$C$11*Inputs!$C$79 | D11: =Inputs!$C$11*Inputs!$C$79 | E11: =Inputs!$C$11*Inputs!$C$79 | F11: =Inputs!$C$11*Inputs!$C$79 | G11: =Inputs!$C$11*Inputs!$C$79*Inputs!$C$86 | I11: =Inputs!$C$11*Inputs!$C$80 | J11: =Inputs!$C$11*Inputs!$C$80 | K11: =Inputs!$C$11*Inputs!$C$80 | L11: =Inputs!$C$11*Inputs!$C$80 | M11: =Inputs!$C$11*Inputs!$C$80 | N11: =Inputs!$C$11*Inputs!$C$80*Inputs!$C$86
A12: Operations team | B12: =Inputs!$C$12*Inputs!$C$81 | C12: =Inputs!$C$12*Inputs!$C$81 | D12: =Inputs!$C$12*Inputs!$C$81 | E12: =Inputs!$C$12*Inputs!$C$81 | F12: =Inputs!$C$12*Inputs!$C$81 | G12: =Inputs!$C$12*Inputs!$C$81*Inputs!$C$86 | I12: =Inputs!$C$12*Inputs!$C$82 | J12: =Inputs!$C$12*Inputs!$C$82 | K12: =Inputs!$C$12*Inputs!$C$82 | L12: =Inputs!$C$12*Inputs!$C$82 | M12: =Inputs!$C$12*Inputs!$C$82 | N12: =Inputs!$C$12*Inputs!$C$82*Inputs!$C$86
A13: Superadmin (vendor) | B13: =Inputs!$C$85*Inputs!$C$83 | C13: =Inputs!$C$85*Inputs!$C$83 | D13: =Inputs!$C$85*Inputs!$C$83 | E13: =Inputs!$C$85*Inputs!$C$83 | F13: =Inputs!$C$85*Inputs!$C$83 | G13: =0 | I13: =Inputs!$C$13*Inputs!$C$84 | J13: =Inputs!$C$13*Inputs!$C$84 | K13: =Inputs!$C$13*Inputs!$C$84 | L13: =Inputs!$C$13*Inputs!$C$84 | M13: =Inputs!$C$13*Inputs!$C$84 | N13: =0
A14: STAFF SUBTOTAL | B14: =SUM(B6:B13) | C14: =SUM(C6:C13) | D14: =SUM(D6:D13) | E14: =SUM(E6:E13) | F14: =SUM(F6:F13) | G14: =SUM(G6:G13) | I14: =SUM(I6:I13) | J14: =SUM(J6:J13) | K14: =SUM(K6:K13) | L14: =SUM(L6:L13) | M14: =SUM(M6:M13) | N14: =SUM(N6:N13)
A15: Assessments (online tests) | B15: =0 | C15: ='Usage Model'!$B$23*Inputs!$C$90 | D15: =0 | E15: =0 | F15: =0 | G15: =0 | I15: =0 | J15: ='Usage Model'!$B$23*Inputs!$C$91 | K15: =0 | L15: =0 | M15: =0 | N15: =0
A16: Assignments | B16: ='Usage Model'!$B$24*Inputs!$C$94 | C16: =0 | D16: =0 | E16: =0 | F16: =0 | G16: =0 | I16: ='Usage Model'!$B$24*Inputs!$C$95 | J16: =0 | K16: =0 | L16: =0 | M16: =0 | N16: =0
A17: Library loans + visits | B17: ='Usage Model'!$B$25*Inputs!$C$103 | C17: ='Usage Model'!$B$25*Inputs!$C$103 | D17: =0 | E17: =0 | F17: =0 | G17: =0 | I17: ='Usage Model'!$B$25*Inputs!$C$104+'Usage Model'!$B$26 | J17: ='Usage Model'!$B$25*Inputs!$C$104+'Usage Model'!$B$26 | K17: =0 | L17: =0 | M17: =0 | N17: =0
A18: EVENTS SUBTOTAL | B18: =SUM(B15:B17) | C18: =SUM(C15:C17) | D18: =SUM(D15:D17) | E18: =SUM(E15:E17) | F18: =SUM(F15:F17) | G18: =SUM(G15:G17) | I18: =SUM(I15:I17) | J18: =SUM(J15:J17) | K18: =SUM(K15:K17) | L18: =SUM(L15:L17) | M18: =SUM(M15:M17) | N18: =SUM(N15:N17)
A19: TOTAL per day | B19: =B5+B14+B18 | C19: =C5+C14+C18 | D19: =D5+D14+D18 | E19: =E5+E14+E18 | F19: =F5+F14+F18 | G19: =G5+G14+G18 | I19: =I5+I14+I18 | J19: =J5+J14+J18 | K19: =K5+K14+K18 | L19: =L5+L14+L18 | M19: =M5+M14+M18 | N19: =N5+N14+N18
A20: Free quota covers | B20: =IF(B19>0,MIN(1,Inputs!$C$26/B19),1) | C20: =IF(C19>0,MIN(1,Inputs!$C$26/C19),1) | D20: =IF(D19>0,MIN(1,Inputs!$C$26/D19),1) | E20: =IF(E19>0,MIN(1,Inputs!$C$26/E19),1) | F20: =IF(F19>0,MIN(1,Inputs!$C$26/F19),1) | G20: =IF(G19>0,MIN(1,Inputs!$C$26/G19),1) | I20: =IF(I19>0,MIN(1,Inputs!$C$27/I19),1) | J20: =IF(J19>0,MIN(1,Inputs!$C$27/J19),1) | K20: =IF(K19>0,MIN(1,Inputs!$C$27/K19),1) | L20: =IF(L19>0,MIN(1,Inputs!$C$27/L19),1) | M20: =IF(M19>0,MIN(1,Inputs!$C$27/M19),1) | N20: =IF(N19>0,MIN(1,Inputs!$C$27/N19),1)
A22: Event rates
A23: Test attempts per IA day | B23: =Inputs!$C$6*Inputs!$C$89/Calendar!$C$16
A24: Assignment submissions per teaching day | B24: =Inputs!$C$6*Inputs!$C$93/Calendar!$B$16
A25: Library loan cycles per class day | B25: =Inputs!$C$6*Inputs!$C$102/(Calendar!$B$16+Calendar!$C$16)
A26: Library visits per class day | B26: =Inputs!$C$6*Inputs!$C$105/(Calendar!$B$16+Calendar!$C$16)
A28: B. Month-by-month grid (free quota applied per day; bursts are fully billable because they land on days already over quota)
A29: Month | B29: Teach | C29: IA | D29: Uni | E29: Result | F29: Office | G29: Off | H29: Working days | I29: Ramp | J29: Att. reads / load | K29: Fee collections | L29: Admissions | M29: Spread reads / working day | N29: Spread writes / working day | O29: Reads/day Teach | P29: Reads/day IA | Q29: Reads/day Uni | R29: Reads/day Result | S29: Reads/day Office | T29: Reads/day Off | U29: Writes/day Teach | V29: Writes/day IA | W29: Writes/day Uni | X29: Writes/day Result | Y29: Writes/day Office | Z29: Writes/day Off | AA29: Burst reads | AB29: Burst writes | AC29: TOTAL reads | AD29: TOTAL writes | AE29: BILLABLE reads | AF29: BILLABLE writes | AG29: Function invocations | AH29: Attendance docs added | AI29: Firestore GiB (cum.) | AJ29: Files GB added | AK29: Files GB (cum.) | AL29: Downloads GB | AM29: Hosting GB | AN29: Peak reads / day
A30: =Calendar!A4 | B30: =Calendar!B4 | C30: =Calendar!C4 | D30: =Calendar!D4 | E30: =Calendar!E4 | F30: =Calendar!F4 | G30: =Calendar!G4 | H30: =Calendar!H4 | I30: =Calendar!J4 | J30: =Inputs!$C$50*I30 | K30: =Inputs!$C$98*Calendar!K4 | L30: =Inputs!$C$20*Calendar!L4 | M30: =IF(H30>0,(K30*Inputs!$C$99+L30*Inputs!$C$109)/H30,0) | N30: =IF(H30>0,(K30*Inputs!$C$100+L30*Inputs!$C$110)/H30,0) | O30: =Inputs!$C$6*Inputs!$C$42*(Inputs!$C$47*(Inputs!$C$49+J30)+Inputs!$C$51)+B$14+B$18+M30 | P30: =Inputs!$C$6*Inputs!$C$43*(Inputs!$C$47*(Inputs!$C$49+J30)+Inputs!$C$51)+C$14+C$18+M30 | Q30: =Inputs!$C$6*Inputs!$C$44*(Inputs!$C$48*(Inputs!$C$49+J30)+Inputs!$C$52)+D$14+D$18+M30 | R30: =Inputs!$C$6*Inputs!$C$45*(Inputs!$C$48*(Inputs!$C$49+J30)+Inputs!$C$53)+E$14+E$18+M30 | S30: =Inputs!$C$6*Inputs!$C$46*(Inputs!$C$48*(Inputs!$C$49+J30)+Inputs!$C$53)+F$14+F$18+M30 | T30: =Inputs!$C$6*Inputs!$C$46*(Inputs!$C$48*(Inputs!$C$49+J30)+Inputs!$C$53)+G$14+G$18 | U30: =Inputs!$C$6*Inputs!$C$42*Inputs!$C$54+I$14+I$18+N30 | V30: =Inputs!$C$6*Inputs!$C$43*Inputs!$C$54+J$14+J$18+N30 | W30: =Inputs!$C$6*Inputs!$C$44*Inputs!$C$55+K$14+K$18+N30 | X30: =Inputs!$C$6*Inputs!$C$45*Inputs!$C$55+L$14+L$18+N30 | Y30: =Inputs!$C$6*Inputs!$C$46*Inputs!$C$55+M$14+M$18+N30 | Z30: =Inputs!$C$6*Inputs!$C$46*Inputs!$C$55+N$14+N$18 | AA30: =Calendar!M4*Inputs!$C$6+Calendar!E4*Inputs!$C$6+Calendar!Q4*Inputs!$C$112+Inputs!$C$6*Inputs!$C$106/12+Inputs!$C$108*Inputs!$C$107/12 | AB30: =Calendar!M4*Inputs!$C$6*Inputs!$C$101+Calendar!N4*Inputs!$C$6+Calendar!O4*Inputs!$C$113+Calendar!E4*Inputs!$C$6+Calendar!Q4*Inputs!$C$19*Inputs!$C$111+L30 | AC30: =B30*O30+C30*P30+D30*Q30+E30*R30+F30*S30+G30*T30+AA30 | AD30: =B30*U30+C30*V30+D30*W30+E30*X30+F30*Y30+G30*Z30+AB30 | AE30: =B30*MAX(0,O30-Inputs!$C$26)+C30*MAX(0,P30-Inputs!$C$26)+D30*MAX(0,Q30-Inputs!$C$26)+E30*MAX(0,R30-Inputs!$C$26)+F30*MAX(0,S30-Inputs!$C$26)+G30*MAX(0,T30-Inputs!$C$26)+AA30 | AF30: =B30*MAX(0,U30-Inputs!$C$27)+C30*MAX(0,V30-Inputs!$C$27)+D30*MAX(0,W30-Inputs!$C$27)+E30*MAX(0,X30-Inputs!$C$27)+F30*MAX(0,Y30-Inputs!$C$27)+G30*MAX(0,Z30-Inputs!$C$27)+AB30 | AG30: =Inputs!$C$6*Inputs!$C$42*Inputs!$C$47*Inputs!$C$56*B30+(Inputs!$C$6*Inputs!$C$43*Inputs!$C$47*Inputs!$C$56+'Usage Model'!$B$23*Inputs!$C$92)*C30+Inputs!$C$6*Inputs!$C$44*Inputs!$C$48*Inputs!$C$56*D30+Inputs!$C$6*Inputs!$C$45*Inputs!$C$48*Inputs!$C$56*E30+Inputs!$C$6*Inputs!$C$46*Inputs!$C$48*Inputs!$C$56*(F30+G30)+'Usage Model'!$B$24*Inputs!$C$96*B30 | AH30: =Inputs!$C$18*Inputs!$C$15*(B30+C30*Inputs!$C$76) | AI30: =Inputs!$C$124+AH30*Inputs!$C$118/1048576+('Usage Model'!$B$26*(B30+C30)*0.5+'Usage Model'!$B$25*(B30+C30))/1048576+'Usage Model'!$B$23*C30*Inputs!$C$119/1048576+0.05 | AJ30: ='Usage Model'!$B$24*B30*Inputs!$C$97/1024+(Calendar!M4+Calendar!P4)*Inputs!$C$6*Inputs!$C$117/1048576+L30*3/1024+Inputs!$C$125+Inputs!$C$126 | AK30: =0+AJ30 | AL30: =(Inputs!$C$6*Inputs!$C$116*Inputs!$C$115/1024)*(B30+C30)/(Calendar!$B$16+Calendar!$C$16)+'Usage Model'!$B$24*B30*Inputs!$C$97/1024+(Calendar!M4+Calendar!P4)*Inputs!$C$6*Inputs!$C$117/1048576*2 | AM30: =Inputs!$C$14*Inputs!$C$120*Inputs!$C$121/1024+(Inputs!$C$6*Inputs!$C$123+Inputs!$C$7)*Inputs!$C$122*30/1048576 | AN30: =MAX(O30:T30)
A31: =Calendar!A5 | B31: =Calendar!B5 | C31: =Calendar!C5 | D31: =Calendar!D5 | E31: =Calendar!E5 | F31: =Calendar!F5 | G31: =Calendar!G5 | H31: =Calendar!H5 | I31: =Calendar!J5 | J31: =Inputs!$C$50*I31 | K31: =Inputs!$C$98*Calendar!K5 | L31: =Inputs!$C$20*Calendar!L5 | M31: =IF(H31>0,(K31*Inputs!$C$99+L31*Inputs!$C$109)/H31,0) | N31: =IF(H31>0,(K31*Inputs!$C$100+L31*Inputs!$C$110)/H31,0) | O31: =Inputs!$C$6*Inputs!$C$42*(Inputs!$C$47*(Inputs!$C$49+J31)+Inputs!$C$51)+B$14+B$18+M31 | P31: =Inputs!$C$6*Inputs!$C$43*(Inputs!$C$47*(Inputs!$C$49+J31)+Inputs!$C$51)+C$14+C$18+M31 | Q31: =Inputs!$C$6*Inputs!$C$44*(Inputs!$C$48*(Inputs!$C$49+J31)+Inputs!$C$52)+D$14+D$18+M31 | R31: =Inputs!$C$6*Inputs!$C$45*(Inputs!$C$48*(Inputs!$C$49+J31)+Inputs!$C$53)+E$14+E$18+M31 | S31: =Inputs!$C$6*Inputs!$C$46*(Inputs!$C$48*(Inputs!$C$49+J31)+Inputs!$C$53)+F$14+F$18+M31 | T31: =Inputs!$C$6*Inputs!$C$46*(Inputs!$C$48*(Inputs!$C$49+J31)+Inputs!$C$53)+G$14+G$18 | U31: =Inputs!$C$6*Inputs!$C$42*Inputs!$C$54+I$14+I$18+N31 | V31: =Inputs!$C$6*Inputs!$C$43*Inputs!$C$54+J$14+J$18+N31 | W31: =Inputs!$C$6*Inputs!$C$44*Inputs!$C$55+K$14+K$18+N31 | X31: =Inputs!$C$6*Inputs!$C$45*Inputs!$C$55+L$14+L$18+N31 | Y31: =Inputs!$C$6*Inputs!$C$46*Inputs!$C$55+M$14+M$18+N31 | Z31: =Inputs!$C$6*Inputs!$C$46*Inputs!$C$55+N$14+N$18 | AA31: =Calendar!M5*Inputs!$C$6+Calendar!E5*Inputs!$C$6+Calendar!Q5*Inputs!$C$112+Inputs!$C$6*Inputs!$C$106/12+Inputs!$C$108*Inputs!$C$107/12 | AB31: =Calendar!M5*Inputs!$C$6*Inputs!$C$101+Calendar!N5*Inputs!$C$6+Calendar!O5*Inputs!$C$113+Calendar!E5*Inputs!$C$6+Calendar!Q5*Inputs!$C$19*Inputs!$C$111+L31 | AC31: =B31*O31+C31*P31+D31*Q31+E31*R31+F31*S31+G31*T31+AA31 | AD31: =B31*U31+C31*V31+D31*W31+E31*X31+F31*Y31+G31*Z31+AB31 | AE31: =B31*MAX(0,O31-Inputs!$C$26)+C31*MAX(0,P31-Inputs!$C$26)+D31*MAX(0,Q31-Inputs!$C$26)+E31*MAX(0,R31-Inputs!$C$26)+F31*MAX(0,S31-Inputs!$C$26)+G31*MAX(0,T31-Inputs!$C$26)+AA31 | AF31: =B31*MAX(0,U31-Inputs!$C$27)+C31*MAX(0,V31-Inputs!$C$27)+D31*MAX(0,W31-Inputs!$C$27)+E31*MAX(0,X31-Inputs!$C$27)+F31*MAX(0,Y31-Inputs!$C$27)+G31*MAX(0,Z31-Inputs!$C$27)+AB31 | AG31: =Inputs!$C$6*Inputs!$C$42*Inputs!$C$47*Inputs!$C$56*B31+(Inputs!$C$6*Inputs!$C$43*Inputs!$C$47*Inputs!$C$56+'Usage Model'!$B$23*Inputs!$C$92)*C31+Inputs!$C$6*Inputs!$C$44*Inputs!$C$48*Inputs!$C$56*D31+Inputs!$C$6*Inputs!$C$45*Inputs!$C$48*Inputs!$C$56*E31+Inputs!$C$6*Inputs!$C$46*Inputs!$C$48*Inputs!$C$56*(F31+G31)+'Usage Model'!$B$24*Inputs!$C$96*B31 | AH31: =Inputs!$C$18*Inputs!$C$15*(B31+C31*Inputs!$C$76) | AI31: =AI30+AH31*Inputs!$C$118/1048576+('Usage Model'!$B$26*(B31+C31)*0.5+'Usage Model'!$B$25*(B31+C31))/1048576+'Usage Model'!$B$23*C31*Inputs!$C$119/1048576+0.05 | AJ31: ='Usage Model'!$B$24*B31*Inputs!$C$97/1024+(Calendar!M5+Calendar!P5)*Inputs!$C$6*Inputs!$C$117/1048576+L31*3/1024 | AK31: =AK30+AJ31 | AL31: =(Inputs!$C$6*Inputs!$C$116*Inputs!$C$115/1024)*(B31+C31)/(Calendar!$B$16+Calendar!$C$16)+'Usage Model'!$B$24*B31*Inputs!$C$97/1024+(Calendar!M5+Calendar!P5)*Inputs!$C$6*Inputs!$C$117/1048576*2 | AM31: =Inputs!$C$14*Inputs!$C$120*Inputs!$C$121/1024+(Inputs!$C$6*Inputs!$C$123+Inputs!$C$7)*Inputs!$C$122*30/1048576 | AN31: =MAX(O31:T31)
A32: =Calendar!A6 | B32: =Calendar!B6 | C32: =Calendar!C6 | D32: =Calendar!D6 | E32: =Calendar!E6 | F32: =Calendar!F6 | G32: =Calendar!G6 | H32: =Calendar!H6 | I32: =Calendar!J6 | J32: =Inputs!$C$50*I32 | K32: =Inputs!$C$98*Calendar!K6 | L32: =Inputs!$C$20*Calendar!L6 | M32: =IF(H32>0,(K32*Inputs!$C$99+L32*Inputs!$C$109)/H32,0) | N32: =IF(H32>0,(K32*Inputs!$C$100+L32*Inputs!$C$110)/H32,0) | O32: =Inputs!$C$6*Inputs!$C$42*(Inputs!$C$47*(Inputs!$C$49+J32)+Inputs!$C$51)+B$14+B$18+M32 | P32: =Inputs!$C$6*Inputs!$C$43*(Inputs!$C$47*(Inputs!$C$49+J32)+Inputs!$C$51)+C$14+C$18+M32 | Q32: =Inputs!$C$6*Inputs!$C$44*(Inputs!$C$48*(Inputs!$C$49+J32)+Inputs!$C$52)+D$14+D$18+M32 | R32: =Inputs!$C$6*Inputs!$C$45*(Inputs!$C$48*(Inputs!$C$49+J32)+Inputs!$C$53)+E$14+E$18+M32 | S32: =Inputs!$C$6*Inputs!$C$46*(Inputs!$C$48*(Inputs!$C$49+J32)+Inputs!$C$53)+F$14+F$18+M32 | T32: =Inputs!$C$6*Inputs!$C$46*(Inputs!$C$48*(Inputs!$C$49+J32)+Inputs!$C$53)+G$14+G$18 | U32: =Inputs!$C$6*Inputs!$C$42*Inputs!$C$54+I$14+I$18+N32 | V32: =Inputs!$C$6*Inputs!$C$43*Inputs!$C$54+J$14+J$18+N32 | W32: =Inputs!$C$6*Inputs!$C$44*Inputs!$C$55+K$14+K$18+N32 | X32: =Inputs!$C$6*Inputs!$C$45*Inputs!$C$55+L$14+L$18+N32 | Y32: =Inputs!$C$6*Inputs!$C$46*Inputs!$C$55+M$14+M$18+N32 | Z32: =Inputs!$C$6*Inputs!$C$46*Inputs!$C$55+N$14+N$18 | AA32: =Calendar!M6*Inputs!$C$6+Calendar!E6*Inputs!$C$6+Calendar!Q6*Inputs!$C$112+Inputs!$C$6*Inputs!$C$106/12+Inputs!$C$108*Inputs!$C$107/12 | AB32: =Calendar!M6*Inputs!$C$6*Inputs!$C$101+Calendar!N6*Inputs!$C$6+Calendar!O6*Inputs!$C$113+Calendar!E6*Inputs!$C$6+Calendar!Q6*Inputs!$C$19*Inputs!$C$111+L32 | AC32: =B32*O32+C32*P32+D32*Q32+E32*R32+F32*S32+G32*T32+AA32 | AD32: =B32*U32+C32*V32+D32*W32+E32*X32+F32*Y32+G32*Z32+AB32 | AE32: =B32*MAX(0,O32-Inputs!$C$26)+C32*MAX(0,P32-Inputs!$C$26)+D32*MAX(0,Q32-Inputs!$C$26)+E32*MAX(0,R32-Inputs!$C$26)+F32*MAX(0,S32-Inputs!$C$26)+G32*MAX(0,T32-Inputs!$C$26)+AA32 | AF32: =B32*MAX(0,U32-Inputs!$C$27)+C32*MAX(0,V32-Inputs!$C$27)+D32*MAX(0,W32-Inputs!$C$27)+E32*MAX(0,X32-Inputs!$C$27)+F32*MAX(0,Y32-Inputs!$C$27)+G32*MAX(0,Z32-Inputs!$C$27)+AB32 | AG32: =Inputs!$C$6*Inputs!$C$42*Inputs!$C$47*Inputs!$C$56*B32+(Inputs!$C$6*Inputs!$C$43*Inputs!$C$47*Inputs!$C$56+'Usage Model'!$B$23*Inputs!$C$92)*C32+Inputs!$C$6*Inputs!$C$44*Inputs!$C$48*Inputs!$C$56*D32+Inputs!$C$6*Inputs!$C$45*Inputs!$C$48*Inputs!$C$56*E32+Inputs!$C$6*Inputs!$C$46*Inputs!$C$48*Inputs!$C$56*(F32+G32)+'Usage Model'!$B$24*Inputs!$C$96*B32 | AH32: =Inputs!$C$18*Inputs!$C$15*(B32+C32*Inputs!$C$76) | AI32: =AI31+AH32*Inputs!$C$118/1048576+('Usage Model'!$B$26*(B32+C32)*0.5+'Usage Model'!$B$25*(B32+C32))/1048576+'Usage Model'!$B$23*C32*Inputs!$C$119/1048576+0.05 | AJ32: ='Usage Model'!$B$24*B32*Inputs!$C$97/1024+(Calendar!M6+Calendar!P6)*Inputs!$C$6*Inputs!$C$117/1048576+L32*3/1024 | AK32: =AK31+AJ32 | AL32: =(Inputs!$C$6*Inputs!$C$116*Inputs!$C$115/1024)*(B32+C32)/(Calendar!$B$16+Calendar!$C$16)+'Usage Model'!$B$24*B32*Inputs!$C$97/1024+(Calendar!M6+Calendar!P6)*Inputs!$C$6*Inputs!$C$117/1048576*2 | AM32: =Inputs!$C$14*Inputs!$C$120*Inputs!$C$121/1024+(Inputs!$C$6*Inputs!$C$123+Inputs!$C$7)*Inputs!$C$122*30/1048576 | AN32: =MAX(O32:T32)
A33: =Calendar!A7 | B33: =Calendar!B7 | C33: =Calendar!C7 | D33: =Calendar!D7 | E33: =Calendar!E7 | F33: =Calendar!F7 | G33: =Calendar!G7 | H33: =Calendar!H7 | I33: =Calendar!J7 | J33: =Inputs!$C$50*I33 | K33: =Inputs!$C$98*Calendar!K7 | L33: =Inputs!$C$20*Calendar!L7 | M33: =IF(H33>0,(K33*Inputs!$C$99+L33*Inputs!$C$109)/H33,0) | N33: =IF(H33>0,(K33*Inputs!$C$100+L33*Inputs!$C$110)/H33,0) | O33: =Inputs!$C$6*Inputs!$C$42*(Inputs!$C$47*(Inputs!$C$49+J33)+Inputs!$C$51)+B$14+B$18+M33 | P33: =Inputs!$C$6*Inputs!$C$43*(Inputs!$C$47*(Inputs!$C$49+J33)+Inputs!$C$51)+C$14+C$18+M33 | Q33: =Inputs!$C$6*Inputs!$C$44*(Inputs!$C$48*(Inputs!$C$49+J33)+Inputs!$C$52)+D$14+D$18+M33 | R33: =Inputs!$C$6*Inputs!$C$45*(Inputs!$C$48*(Inputs!$C$49+J33)+Inputs!$C$53)+E$14+E$18+M33 | S33: =Inputs!$C$6*Inputs!$C$46*(Inputs!$C$48*(Inputs!$C$49+J33)+Inputs!$C$53)+F$14+F$18+M33 | T33: =Inputs!$C$6*Inputs!$C$46*(Inputs!$C$48*(Inputs!$C$49+J33)+Inputs!$C$53)+G$14+G$18 | U33: =Inputs!$C$6*Inputs!$C$42*Inputs!$C$54+I$14+I$18+N33 | V33: =Inputs!$C$6*Inputs!$C$43*Inputs!$C$54+J$14+J$18+N33 | W33: =Inputs!$C$6*Inputs!$C$44*Inputs!$C$55+K$14+K$18+N33 | X33: =Inputs!$C$6*Inputs!$C$45*Inputs!$C$55+L$14+L$18+N33 | Y33: =Inputs!$C$6*Inputs!$C$46*Inputs!$C$55+M$14+M$18+N33 | Z33: =Inputs!$C$6*Inputs!$C$46*Inputs!$C$55+N$14+N$18 | AA33: =Calendar!M7*Inputs!$C$6+Calendar!E7*Inputs!$C$6+Calendar!Q7*Inputs!$C$112+Inputs!$C$6*Inputs!$C$106/12+Inputs!$C$108*Inputs!$C$107/12 | AB33: =Calendar!M7*Inputs!$C$6*Inputs!$C$101+Calendar!N7*Inputs!$C$6+Calendar!O7*Inputs!$C$113+Calendar!E7*Inputs!$C$6+Calendar!Q7*Inputs!$C$19*Inputs!$C$111+L33 | AC33: =B33*O33+C33*P33+D33*Q33+E33*R33+F33*S33+G33*T33+AA33 | AD33: =B33*U33+C33*V33+D33*W33+E33*X33+F33*Y33+G33*Z33+AB33 | AE33: =B33*MAX(0,O33-Inputs!$C$26)+C33*MAX(0,P33-Inputs!$C$26)+D33*MAX(0,Q33-Inputs!$C$26)+E33*MAX(0,R33-Inputs!$C$26)+F33*MAX(0,S33-Inputs!$C$26)+G33*MAX(0,T33-Inputs!$C$26)+AA33 | AF33: =B33*MAX(0,U33-Inputs!$C$27)+C33*MAX(0,V33-Inputs!$C$27)+D33*MAX(0,W33-Inputs!$C$27)+E33*MAX(0,X33-Inputs!$C$27)+F33*MAX(0,Y33-Inputs!$C$27)+G33*MAX(0,Z33-Inputs!$C$27)+AB33 | AG33: =Inputs!$C$6*Inputs!$C$42*Inputs!$C$47*Inputs!$C$56*B33+(Inputs!$C$6*Inputs!$C$43*Inputs!$C$47*Inputs!$C$56+'Usage Model'!$B$23*Inputs!$C$92)*C33+Inputs!$C$6*Inputs!$C$44*Inputs!$C$48*Inputs!$C$56*D33+Inputs!$C$6*Inputs!$C$45*Inputs!$C$48*Inputs!$C$56*E33+Inputs!$C$6*Inputs!$C$46*Inputs!$C$48*Inputs!$C$56*(F33+G33)+'Usage Model'!$B$24*Inputs!$C$96*B33 | AH33: =Inputs!$C$18*Inputs!$C$15*(B33+C33*Inputs!$C$76) | AI33: =AI32+AH33*Inputs!$C$118/1048576+('Usage Model'!$B$26*(B33+C33)*0.5+'Usage Model'!$B$25*(B33+C33))/1048576+'Usage Model'!$B$23*C33*Inputs!$C$119/1048576+0.05 | AJ33: ='Usage Model'!$B$24*B33*Inputs!$C$97/1024+(Calendar!M7+Calendar!P7)*Inputs!$C$6*Inputs!$C$117/1048576+L33*3/1024 | AK33: =AK32+AJ33 | AL33: =(Inputs!$C$6*Inputs!$C$116*Inputs!$C$115/1024)*(B33+C33)/(Calendar!$B$16+Calendar!$C$16)+'Usage Model'!$B$24*B33*Inputs!$C$97/1024+(Calendar!M7+Calendar!P7)*Inputs!$C$6*Inputs!$C$117/1048576*2 | AM33: =Inputs!$C$14*Inputs!$C$120*Inputs!$C$121/1024+(Inputs!$C$6*Inputs!$C$123+Inputs!$C$7)*Inputs!$C$122*30/1048576 | AN33: =MAX(O33:T33)
A34: =Calendar!A8 | B34: =Calendar!B8 | C34: =Calendar!C8 | D34: =Calendar!D8 | E34: =Calendar!E8 | F34: =Calendar!F8 | G34: =Calendar!G8 | H34: =Calendar!H8 | I34: =Calendar!J8 | J34: =Inputs!$C$50*I34 | K34: =Inputs!$C$98*Calendar!K8 | L34: =Inputs!$C$20*Calendar!L8 | M34: =IF(H34>0,(K34*Inputs!$C$99+L34*Inputs!$C$109)/H34,0) | N34: =IF(H34>0,(K34*Inputs!$C$100+L34*Inputs!$C$110)/H34,0) | O34: =Inputs!$C$6*Inputs!$C$42*(Inputs!$C$47*(Inputs!$C$49+J34)+Inputs!$C$51)+B$14+B$18+M34 | P34: =Inputs!$C$6*Inputs!$C$43*(Inputs!$C$47*(Inputs!$C$49+J34)+Inputs!$C$51)+C$14+C$18+M34 | Q34: =Inputs!$C$6*Inputs!$C$44*(Inputs!$C$48*(Inputs!$C$49+J34)+Inputs!$C$52)+D$14+D$18+M34 | R34: =Inputs!$C$6*Inputs!$C$45*(Inputs!$C$48*(Inputs!$C$49+J34)+Inputs!$C$53)+E$14+E$18+M34 | S34: =Inputs!$C$6*Inputs!$C$46*(Inputs!$C$48*(Inputs!$C$49+J34)+Inputs!$C$53)+F$14+F$18+M34 | T34: =Inputs!$C$6*Inputs!$C$46*(Inputs!$C$48*(Inputs!$C$49+J34)+Inputs!$C$53)+G$14+G$18 | U34: =Inputs!$C$6*Inputs!$C$42*Inputs!$C$54+I$14+I$18+N34 | V34: =Inputs!$C$6*Inputs!$C$43*Inputs!$C$54+J$14+J$18+N34 | W34: =Inputs!$C$6*Inputs!$C$44*Inputs!$C$55+K$14+K$18+N34 | X34: =Inputs!$C$6*Inputs!$C$45*Inputs!$C$55+L$14+L$18+N34 | Y34: =Inputs!$C$6*Inputs!$C$46*Inputs!$C$55+M$14+M$18+N34 | Z34: =Inputs!$C$6*Inputs!$C$46*Inputs!$C$55+N$14+N$18 | AA34: =Calendar!M8*Inputs!$C$6+Calendar!E8*Inputs!$C$6+Calendar!Q8*Inputs!$C$112+Inputs!$C$6*Inputs!$C$106/12+Inputs!$C$108*Inputs!$C$107/12 | AB34: =Calendar!M8*Inputs!$C$6*Inputs!$C$101+Calendar!N8*Inputs!$C$6+Calendar!O8*Inputs!$C$113+Calendar!E8*Inputs!$C$6+Calendar!Q8*Inputs!$C$19*Inputs!$C$111+L34 | AC34: =B34*O34+C34*P34+D34*Q34+E34*R34+F34*S34+G34*T34+AA34 | AD34: =B34*U34+C34*V34+D34*W34+E34*X34+F34*Y34+G34*Z34+AB34 | AE34: =B34*MAX(0,O34-Inputs!$C$26)+C34*MAX(0,P34-Inputs!$C$26)+D34*MAX(0,Q34-Inputs!$C$26)+E34*MAX(0,R34-Inputs!$C$26)+F34*MAX(0,S34-Inputs!$C$26)+G34*MAX(0,T34-Inputs!$C$26)+AA34 | AF34: =B34*MAX(0,U34-Inputs!$C$27)+C34*MAX(0,V34-Inputs!$C$27)+D34*MAX(0,W34-Inputs!$C$27)+E34*MAX(0,X34-Inputs!$C$27)+F34*MAX(0,Y34-Inputs!$C$27)+G34*MAX(0,Z34-Inputs!$C$27)+AB34 | AG34: =Inputs!$C$6*Inputs!$C$42*Inputs!$C$47*Inputs!$C$56*B34+(Inputs!$C$6*Inputs!$C$43*Inputs!$C$47*Inputs!$C$56+'Usage Model'!$B$23*Inputs!$C$92)*C34+Inputs!$C$6*Inputs!$C$44*Inputs!$C$48*Inputs!$C$56*D34+Inputs!$C$6*Inputs!$C$45*Inputs!$C$48*Inputs!$C$56*E34+Inputs!$C$6*Inputs!$C$46*Inputs!$C$48*Inputs!$C$56*(F34+G34)+'Usage Model'!$B$24*Inputs!$C$96*B34 | AH34: =Inputs!$C$18*Inputs!$C$15*(B34+C34*Inputs!$C$76) | AI34: =AI33+AH34*Inputs!$C$118/1048576+('Usage Model'!$B$26*(B34+C34)*0.5+'Usage Model'!$B$25*(B34+C34))/1048576+'Usage Model'!$B$23*C34*Inputs!$C$119/1048576+0.05 | AJ34: ='Usage Model'!$B$24*B34*Inputs!$C$97/1024+(Calendar!M8+Calendar!P8)*Inputs!$C$6*Inputs!$C$117/1048576+L34*3/1024 | AK34: =AK33+AJ34 | AL34: =(Inputs!$C$6*Inputs!$C$116*Inputs!$C$115/1024)*(B34+C34)/(Calendar!$B$16+Calendar!$C$16)+'Usage Model'!$B$24*B34*Inputs!$C$97/1024+(Calendar!M8+Calendar!P8)*Inputs!$C$6*Inputs!$C$117/1048576*2 | AM34: =Inputs!$C$14*Inputs!$C$120*Inputs!$C$121/1024+(Inputs!$C$6*Inputs!$C$123+Inputs!$C$7)*Inputs!$C$122*30/1048576 | AN34: =MAX(O34:T34)
A35: =Calendar!A9 | B35: =Calendar!B9 | C35: =Calendar!C9 | D35: =Calendar!D9 | E35: =Calendar!E9 | F35: =Calendar!F9 | G35: =Calendar!G9 | H35: =Calendar!H9 | I35: =Calendar!J9 | J35: =Inputs!$C$50*I35 | K35: =Inputs!$C$98*Calendar!K9 | L35: =Inputs!$C$20*Calendar!L9 | M35: =IF(H35>0,(K35*Inputs!$C$99+L35*Inputs!$C$109)/H35,0) | N35: =IF(H35>0,(K35*Inputs!$C$100+L35*Inputs!$C$110)/H35,0) | O35: =Inputs!$C$6*Inputs!$C$42*(Inputs!$C$47*(Inputs!$C$49+J35)+Inputs!$C$51)+B$14+B$18+M35 | P35: =Inputs!$C$6*Inputs!$C$43*(Inputs!$C$47*(Inputs!$C$49+J35)+Inputs!$C$51)+C$14+C$18+M35 | Q35: =Inputs!$C$6*Inputs!$C$44*(Inputs!$C$48*(Inputs!$C$49+J35)+Inputs!$C$52)+D$14+D$18+M35 | R35: =Inputs!$C$6*Inputs!$C$45*(Inputs!$C$48*(Inputs!$C$49+J35)+Inputs!$C$53)+E$14+E$18+M35 | S35: =Inputs!$C$6*Inputs!$C$46*(Inputs!$C$48*(Inputs!$C$49+J35)+Inputs!$C$53)+F$14+F$18+M35 | T35: =Inputs!$C$6*Inputs!$C$46*(Inputs!$C$48*(Inputs!$C$49+J35)+Inputs!$C$53)+G$14+G$18 | U35: =Inputs!$C$6*Inputs!$C$42*Inputs!$C$54+I$14+I$18+N35 | V35: =Inputs!$C$6*Inputs!$C$43*Inputs!$C$54+J$14+J$18+N35 | W35: =Inputs!$C$6*Inputs!$C$44*Inputs!$C$55+K$14+K$18+N35 | X35: =Inputs!$C$6*Inputs!$C$45*Inputs!$C$55+L$14+L$18+N35 | Y35: =Inputs!$C$6*Inputs!$C$46*Inputs!$C$55+M$14+M$18+N35 | Z35: =Inputs!$C$6*Inputs!$C$46*Inputs!$C$55+N$14+N$18 | AA35: =Calendar!M9*Inputs!$C$6+Calendar!E9*Inputs!$C$6+Calendar!Q9*Inputs!$C$112+Inputs!$C$6*Inputs!$C$106/12+Inputs!$C$108*Inputs!$C$107/12 | AB35: =Calendar!M9*Inputs!$C$6*Inputs!$C$101+Calendar!N9*Inputs!$C$6+Calendar!O9*Inputs!$C$113+Calendar!E9*Inputs!$C$6+Calendar!Q9*Inputs!$C$19*Inputs!$C$111+L35 | AC35: =B35*O35+C35*P35+D35*Q35+E35*R35+F35*S35+G35*T35+AA35 | AD35: =B35*U35+C35*V35+D35*W35+E35*X35+F35*Y35+G35*Z35+AB35 | AE35: =B35*MAX(0,O35-Inputs!$C$26)+C35*MAX(0,P35-Inputs!$C$26)+D35*MAX(0,Q35-Inputs!$C$26)+E35*MAX(0,R35-Inputs!$C$26)+F35*MAX(0,S35-Inputs!$C$26)+G35*MAX(0,T35-Inputs!$C$26)+AA35 | AF35: =B35*MAX(0,U35-Inputs!$C$27)+C35*MAX(0,V35-Inputs!$C$27)+D35*MAX(0,W35-Inputs!$C$27)+E35*MAX(0,X35-Inputs!$C$27)+F35*MAX(0,Y35-Inputs!$C$27)+G35*MAX(0,Z35-Inputs!$C$27)+AB35 | AG35: =Inputs!$C$6*Inputs!$C$42*Inputs!$C$47*Inputs!$C$56*B35+(Inputs!$C$6*Inputs!$C$43*Inputs!$C$47*Inputs!$C$56+'Usage Model'!$B$23*Inputs!$C$92)*C35+Inputs!$C$6*Inputs!$C$44*Inputs!$C$48*Inputs!$C$56*D35+Inputs!$C$6*Inputs!$C$45*Inputs!$C$48*Inputs!$C$56*E35+Inputs!$C$6*Inputs!$C$46*Inputs!$C$48*Inputs!$C$56*(F35+G35)+'Usage Model'!$B$24*Inputs!$C$96*B35 | AH35: =Inputs!$C$18*Inputs!$C$15*(B35+C35*Inputs!$C$76) | AI35: =AI34+AH35*Inputs!$C$118/1048576+('Usage Model'!$B$26*(B35+C35)*0.5+'Usage Model'!$B$25*(B35+C35))/1048576+'Usage Model'!$B$23*C35*Inputs!$C$119/1048576+0.05 | AJ35: ='Usage Model'!$B$24*B35*Inputs!$C$97/1024+(Calendar!M9+Calendar!P9)*Inputs!$C$6*Inputs!$C$117/1048576+L35*3/1024 | AK35: =AK34+AJ35 | AL35: =(Inputs!$C$6*Inputs!$C$116*Inputs!$C$115/1024)*(B35+C35)/(Calendar!$B$16+Calendar!$C$16)+'Usage Model'!$B$24*B35*Inputs!$C$97/1024+(Calendar!M9+Calendar!P9)*Inputs!$C$6*Inputs!$C$117/1048576*2 | AM35: =Inputs!$C$14*Inputs!$C$120*Inputs!$C$121/1024+(Inputs!$C$6*Inputs!$C$123+Inputs!$C$7)*Inputs!$C$122*30/1048576 | AN35: =MAX(O35:T35)
A36: =Calendar!A10 | B36: =Calendar!B10 | C36: =Calendar!C10 | D36: =Calendar!D10 | E36: =Calendar!E10 | F36: =Calendar!F10 | G36: =Calendar!G10 | H36: =Calendar!H10 | I36: =Calendar!J10 | J36: =Inputs!$C$50*I36 | K36: =Inputs!$C$98*Calendar!K10 | L36: =Inputs!$C$20*Calendar!L10 | M36: =IF(H36>0,(K36*Inputs!$C$99+L36*Inputs!$C$109)/H36,0) | N36: =IF(H36>0,(K36*Inputs!$C$100+L36*Inputs!$C$110)/H36,0) | O36: =Inputs!$C$6*Inputs!$C$42*(Inputs!$C$47*(Inputs!$C$49+J36)+Inputs!$C$51)+B$14+B$18+M36 | P36: =Inputs!$C$6*Inputs!$C$43*(Inputs!$C$47*(Inputs!$C$49+J36)+Inputs!$C$51)+C$14+C$18+M36 | Q36: =Inputs!$C$6*Inputs!$C$44*(Inputs!$C$48*(Inputs!$C$49+J36)+Inputs!$C$52)+D$14+D$18+M36 | R36: =Inputs!$C$6*Inputs!$C$45*(Inputs!$C$48*(Inputs!$C$49+J36)+Inputs!$C$53)+E$14+E$18+M36 | S36: =Inputs!$C$6*Inputs!$C$46*(Inputs!$C$48*(Inputs!$C$49+J36)+Inputs!$C$53)+F$14+F$18+M36 | T36: =Inputs!$C$6*Inputs!$C$46*(Inputs!$C$48*(Inputs!$C$49+J36)+Inputs!$C$53)+G$14+G$18 | U36: =Inputs!$C$6*Inputs!$C$42*Inputs!$C$54+I$14+I$18+N36 | V36: =Inputs!$C$6*Inputs!$C$43*Inputs!$C$54+J$14+J$18+N36 | W36: =Inputs!$C$6*Inputs!$C$44*Inputs!$C$55+K$14+K$18+N36 | X36: =Inputs!$C$6*Inputs!$C$45*Inputs!$C$55+L$14+L$18+N36 | Y36: =Inputs!$C$6*Inputs!$C$46*Inputs!$C$55+M$14+M$18+N36 | Z36: =Inputs!$C$6*Inputs!$C$46*Inputs!$C$55+N$14+N$18 | AA36: =Calendar!M10*Inputs!$C$6+Calendar!E10*Inputs!$C$6+Calendar!Q10*Inputs!$C$112+Inputs!$C$6*Inputs!$C$106/12+Inputs!$C$108*Inputs!$C$107/12 | AB36: =Calendar!M10*Inputs!$C$6*Inputs!$C$101+Calendar!N10*Inputs!$C$6+Calendar!O10*Inputs!$C$113+Calendar!E10*Inputs!$C$6+Calendar!Q10*Inputs!$C$19*Inputs!$C$111+L36 | AC36: =B36*O36+C36*P36+D36*Q36+E36*R36+F36*S36+G36*T36+AA36 | AD36: =B36*U36+C36*V36+D36*W36+E36*X36+F36*Y36+G36*Z36+AB36 | AE36: =B36*MAX(0,O36-Inputs!$C$26)+C36*MAX(0,P36-Inputs!$C$26)+D36*MAX(0,Q36-Inputs!$C$26)+E36*MAX(0,R36-Inputs!$C$26)+F36*MAX(0,S36-Inputs!$C$26)+G36*MAX(0,T36-Inputs!$C$26)+AA36 | AF36: =B36*MAX(0,U36-Inputs!$C$27)+C36*MAX(0,V36-Inputs!$C$27)+D36*MAX(0,W36-Inputs!$C$27)+E36*MAX(0,X36-Inputs!$C$27)+F36*MAX(0,Y36-Inputs!$C$27)+G36*MAX(0,Z36-Inputs!$C$27)+AB36 | AG36: =Inputs!$C$6*Inputs!$C$42*Inputs!$C$47*Inputs!$C$56*B36+(Inputs!$C$6*Inputs!$C$43*Inputs!$C$47*Inputs!$C$56+'Usage Model'!$B$23*Inputs!$C$92)*C36+Inputs!$C$6*Inputs!$C$44*Inputs!$C$48*Inputs!$C$56*D36+Inputs!$C$6*Inputs!$C$45*Inputs!$C$48*Inputs!$C$56*E36+Inputs!$C$6*Inputs!$C$46*Inputs!$C$48*Inputs!$C$56*(F36+G36)+'Usage Model'!$B$24*Inputs!$C$96*B36 | AH36: =Inputs!$C$18*Inputs!$C$15*(B36+C36*Inputs!$C$76) | AI36: =AI35+AH36*Inputs!$C$118/1048576+('Usage Model'!$B$26*(B36+C36)*0.5+'Usage Model'!$B$25*(B36+C36))/1048576+'Usage Model'!$B$23*C36*Inputs!$C$119/1048576+0.05 | AJ36: ='Usage Model'!$B$24*B36*Inputs!$C$97/1024+(Calendar!M10+Calendar!P10)*Inputs!$C$6*Inputs!$C$117/1048576+L36*3/1024 | AK36: =AK35+AJ36 | AL36: =(Inputs!$C$6*Inputs!$C$116*Inputs!$C$115/1024)*(B36+C36)/(Calendar!$B$16+Calendar!$C$16)+'Usage Model'!$B$24*B36*Inputs!$C$97/1024+(Calendar!M10+Calendar!P10)*Inputs!$C$6*Inputs!$C$117/1048576*2 | AM36: =Inputs!$C$14*Inputs!$C$120*Inputs!$C$121/1024+(Inputs!$C$6*Inputs!$C$123+Inputs!$C$7)*Inputs!$C$122*30/1048576 | AN36: =MAX(O36:T36)
A37: =Calendar!A11 | B37: =Calendar!B11 | C37: =Calendar!C11 | D37: =Calendar!D11 | E37: =Calendar!E11 | F37: =Calendar!F11 | G37: =Calendar!G11 | H37: =Calendar!H11 | I37: =Calendar!J11 | J37: =Inputs!$C$50*I37 | K37: =Inputs!$C$98*Calendar!K11 | L37: =Inputs!$C$20*Calendar!L11 | M37: =IF(H37>0,(K37*Inputs!$C$99+L37*Inputs!$C$109)/H37,0) | N37: =IF(H37>0,(K37*Inputs!$C$100+L37*Inputs!$C$110)/H37,0) | O37: =Inputs!$C$6*Inputs!$C$42*(Inputs!$C$47*(Inputs!$C$49+J37)+Inputs!$C$51)+B$14+B$18+M37 | P37: =Inputs!$C$6*Inputs!$C$43*(Inputs!$C$47*(Inputs!$C$49+J37)+Inputs!$C$51)+C$14+C$18+M37 | Q37: =Inputs!$C$6*Inputs!$C$44*(Inputs!$C$48*(Inputs!$C$49+J37)+Inputs!$C$52)+D$14+D$18+M37 | R37: =Inputs!$C$6*Inputs!$C$45*(Inputs!$C$48*(Inputs!$C$49+J37)+Inputs!$C$53)+E$14+E$18+M37 | S37: =Inputs!$C$6*Inputs!$C$46*(Inputs!$C$48*(Inputs!$C$49+J37)+Inputs!$C$53)+F$14+F$18+M37 | T37: =Inputs!$C$6*Inputs!$C$46*(Inputs!$C$48*(Inputs!$C$49+J37)+Inputs!$C$53)+G$14+G$18 | U37: =Inputs!$C$6*Inputs!$C$42*Inputs!$C$54+I$14+I$18+N37 | V37: =Inputs!$C$6*Inputs!$C$43*Inputs!$C$54+J$14+J$18+N37 | W37: =Inputs!$C$6*Inputs!$C$44*Inputs!$C$55+K$14+K$18+N37 | X37: =Inputs!$C$6*Inputs!$C$45*Inputs!$C$55+L$14+L$18+N37 | Y37: =Inputs!$C$6*Inputs!$C$46*Inputs!$C$55+M$14+M$18+N37 | Z37: =Inputs!$C$6*Inputs!$C$46*Inputs!$C$55+N$14+N$18 | AA37: =Calendar!M11*Inputs!$C$6+Calendar!E11*Inputs!$C$6+Calendar!Q11*Inputs!$C$112+Inputs!$C$6*Inputs!$C$106/12+Inputs!$C$108*Inputs!$C$107/12 | AB37: =Calendar!M11*Inputs!$C$6*Inputs!$C$101+Calendar!N11*Inputs!$C$6+Calendar!O11*Inputs!$C$113+Calendar!E11*Inputs!$C$6+Calendar!Q11*Inputs!$C$19*Inputs!$C$111+L37 | AC37: =B37*O37+C37*P37+D37*Q37+E37*R37+F37*S37+G37*T37+AA37 | AD37: =B37*U37+C37*V37+D37*W37+E37*X37+F37*Y37+G37*Z37+AB37 | AE37: =B37*MAX(0,O37-Inputs!$C$26)+C37*MAX(0,P37-Inputs!$C$26)+D37*MAX(0,Q37-Inputs!$C$26)+E37*MAX(0,R37-Inputs!$C$26)+F37*MAX(0,S37-Inputs!$C$26)+G37*MAX(0,T37-Inputs!$C$26)+AA37 | AF37: =B37*MAX(0,U37-Inputs!$C$27)+C37*MAX(0,V37-Inputs!$C$27)+D37*MAX(0,W37-Inputs!$C$27)+E37*MAX(0,X37-Inputs!$C$27)+F37*MAX(0,Y37-Inputs!$C$27)+G37*MAX(0,Z37-Inputs!$C$27)+AB37 | AG37: =Inputs!$C$6*Inputs!$C$42*Inputs!$C$47*Inputs!$C$56*B37+(Inputs!$C$6*Inputs!$C$43*Inputs!$C$47*Inputs!$C$56+'Usage Model'!$B$23*Inputs!$C$92)*C37+Inputs!$C$6*Inputs!$C$44*Inputs!$C$48*Inputs!$C$56*D37+Inputs!$C$6*Inputs!$C$45*Inputs!$C$48*Inputs!$C$56*E37+Inputs!$C$6*Inputs!$C$46*Inputs!$C$48*Inputs!$C$56*(F37+G37)+'Usage Model'!$B$24*Inputs!$C$96*B37 | AH37: =Inputs!$C$18*Inputs!$C$15*(B37+C37*Inputs!$C$76) | AI37: =AI36+AH37*Inputs!$C$118/1048576+('Usage Model'!$B$26*(B37+C37)*0.5+'Usage Model'!$B$25*(B37+C37))/1048576+'Usage Model'!$B$23*C37*Inputs!$C$119/1048576+0.05 | AJ37: ='Usage Model'!$B$24*B37*Inputs!$C$97/1024+(Calendar!M11+Calendar!P11)*Inputs!$C$6*Inputs!$C$117/1048576+L37*3/1024 | AK37: =AK36+AJ37 | AL37: =(Inputs!$C$6*Inputs!$C$116*Inputs!$C$115/1024)*(B37+C37)/(Calendar!$B$16+Calendar!$C$16)+'Usage Model'!$B$24*B37*Inputs!$C$97/1024+(Calendar!M11+Calendar!P11)*Inputs!$C$6*Inputs!$C$117/1048576*2 | AM37: =Inputs!$C$14*Inputs!$C$120*Inputs!$C$121/1024+(Inputs!$C$6*Inputs!$C$123+Inputs!$C$7)*Inputs!$C$122*30/1048576 | AN37: =MAX(O37:T37)
A38: =Calendar!A12 | B38: =Calendar!B12 | C38: =Calendar!C12 | D38: =Calendar!D12 | E38: =Calendar!E12 | F38: =Calendar!F12 | G38: =Calendar!G12 | H38: =Calendar!H12 | I38: =Calendar!J12 | J38: =Inputs!$C$50*I38 | K38: =Inputs!$C$98*Calendar!K12 | L38: =Inputs!$C$20*Calendar!L12 | M38: =IF(H38>0,(K38*Inputs!$C$99+L38*Inputs!$C$109)/H38,0) | N38: =IF(H38>0,(K38*Inputs!$C$100+L38*Inputs!$C$110)/H38,0) | O38: =Inputs!$C$6*Inputs!$C$42*(Inputs!$C$47*(Inputs!$C$49+J38)+Inputs!$C$51)+B$14+B$18+M38 | P38: =Inputs!$C$6*Inputs!$C$43*(Inputs!$C$47*(Inputs!$C$49+J38)+Inputs!$C$51)+C$14+C$18+M38 | Q38: =Inputs!$C$6*Inputs!$C$44*(Inputs!$C$48*(Inputs!$C$49+J38)+Inputs!$C$52)+D$14+D$18+M38 | R38: =Inputs!$C$6*Inputs!$C$45*(Inputs!$C$48*(Inputs!$C$49+J38)+Inputs!$C$53)+E$14+E$18+M38 | S38: =Inputs!$C$6*Inputs!$C$46*(Inputs!$C$48*(Inputs!$C$49+J38)+Inputs!$C$53)+F$14+F$18+M38 | T38: =Inputs!$C$6*Inputs!$C$46*(Inputs!$C$48*(Inputs!$C$49+J38)+Inputs!$C$53)+G$14+G$18 | U38: =Inputs!$C$6*Inputs!$C$42*Inputs!$C$54+I$14+I$18+N38 | V38: =Inputs!$C$6*Inputs!$C$43*Inputs!$C$54+J$14+J$18+N38 | W38: =Inputs!$C$6*Inputs!$C$44*Inputs!$C$55+K$14+K$18+N38 | X38: =Inputs!$C$6*Inputs!$C$45*Inputs!$C$55+L$14+L$18+N38 | Y38: =Inputs!$C$6*Inputs!$C$46*Inputs!$C$55+M$14+M$18+N38 | Z38: =Inputs!$C$6*Inputs!$C$46*Inputs!$C$55+N$14+N$18 | AA38: =Calendar!M12*Inputs!$C$6+Calendar!E12*Inputs!$C$6+Calendar!Q12*Inputs!$C$112+Inputs!$C$6*Inputs!$C$106/12+Inputs!$C$108*Inputs!$C$107/12 | AB38: =Calendar!M12*Inputs!$C$6*Inputs!$C$101+Calendar!N12*Inputs!$C$6+Calendar!O12*Inputs!$C$113+Calendar!E12*Inputs!$C$6+Calendar!Q12*Inputs!$C$19*Inputs!$C$111+L38 | AC38: =B38*O38+C38*P38+D38*Q38+E38*R38+F38*S38+G38*T38+AA38 | AD38: =B38*U38+C38*V38+D38*W38+E38*X38+F38*Y38+G38*Z38+AB38 | AE38: =B38*MAX(0,O38-Inputs!$C$26)+C38*MAX(0,P38-Inputs!$C$26)+D38*MAX(0,Q38-Inputs!$C$26)+E38*MAX(0,R38-Inputs!$C$26)+F38*MAX(0,S38-Inputs!$C$26)+G38*MAX(0,T38-Inputs!$C$26)+AA38 | AF38: =B38*MAX(0,U38-Inputs!$C$27)+C38*MAX(0,V38-Inputs!$C$27)+D38*MAX(0,W38-Inputs!$C$27)+E38*MAX(0,X38-Inputs!$C$27)+F38*MAX(0,Y38-Inputs!$C$27)+G38*MAX(0,Z38-Inputs!$C$27)+AB38 | AG38: =Inputs!$C$6*Inputs!$C$42*Inputs!$C$47*Inputs!$C$56*B38+(Inputs!$C$6*Inputs!$C$43*Inputs!$C$47*Inputs!$C$56+'Usage Model'!$B$23*Inputs!$C$92)*C38+Inputs!$C$6*Inputs!$C$44*Inputs!$C$48*Inputs!$C$56*D38+Inputs!$C$6*Inputs!$C$45*Inputs!$C$48*Inputs!$C$56*E38+Inputs!$C$6*Inputs!$C$46*Inputs!$C$48*Inputs!$C$56*(F38+G38)+'Usage Model'!$B$24*Inputs!$C$96*B38 | AH38: =Inputs!$C$18*Inputs!$C$15*(B38+C38*Inputs!$C$76) | AI38: =AI37+AH38*Inputs!$C$118/1048576+('Usage Model'!$B$26*(B38+C38)*0.5+'Usage Model'!$B$25*(B38+C38))/1048576+'Usage Model'!$B$23*C38*Inputs!$C$119/1048576+0.05 | AJ38: ='Usage Model'!$B$24*B38*Inputs!$C$97/1024+(Calendar!M12+Calendar!P12)*Inputs!$C$6*Inputs!$C$117/1048576+L38*3/1024 | AK38: =AK37+AJ38 | AL38: =(Inputs!$C$6*Inputs!$C$116*Inputs!$C$115/1024)*(B38+C38)/(Calendar!$B$16+Calendar!$C$16)+'Usage Model'!$B$24*B38*Inputs!$C$97/1024+(Calendar!M12+Calendar!P12)*Inputs!$C$6*Inputs!$C$117/1048576*2 | AM38: =Inputs!$C$14*Inputs!$C$120*Inputs!$C$121/1024+(Inputs!$C$6*Inputs!$C$123+Inputs!$C$7)*Inputs!$C$122*30/1048576 | AN38: =MAX(O38:T38)
A39: =Calendar!A13 | B39: =Calendar!B13 | C39: =Calendar!C13 | D39: =Calendar!D13 | E39: =Calendar!E13 | F39: =Calendar!F13 | G39: =Calendar!G13 | H39: =Calendar!H13 | I39: =Calendar!J13 | J39: =Inputs!$C$50*I39 | K39: =Inputs!$C$98*Calendar!K13 | L39: =Inputs!$C$20*Calendar!L13 | M39: =IF(H39>0,(K39*Inputs!$C$99+L39*Inputs!$C$109)/H39,0) | N39: =IF(H39>0,(K39*Inputs!$C$100+L39*Inputs!$C$110)/H39,0) | O39: =Inputs!$C$6*Inputs!$C$42*(Inputs!$C$47*(Inputs!$C$49+J39)+Inputs!$C$51)+B$14+B$18+M39 | P39: =Inputs!$C$6*Inputs!$C$43*(Inputs!$C$47*(Inputs!$C$49+J39)+Inputs!$C$51)+C$14+C$18+M39 | Q39: =Inputs!$C$6*Inputs!$C$44*(Inputs!$C$48*(Inputs!$C$49+J39)+Inputs!$C$52)+D$14+D$18+M39 | R39: =Inputs!$C$6*Inputs!$C$45*(Inputs!$C$48*(Inputs!$C$49+J39)+Inputs!$C$53)+E$14+E$18+M39 | S39: =Inputs!$C$6*Inputs!$C$46*(Inputs!$C$48*(Inputs!$C$49+J39)+Inputs!$C$53)+F$14+F$18+M39 | T39: =Inputs!$C$6*Inputs!$C$46*(Inputs!$C$48*(Inputs!$C$49+J39)+Inputs!$C$53)+G$14+G$18 | U39: =Inputs!$C$6*Inputs!$C$42*Inputs!$C$54+I$14+I$18+N39 | V39: =Inputs!$C$6*Inputs!$C$43*Inputs!$C$54+J$14+J$18+N39 | W39: =Inputs!$C$6*Inputs!$C$44*Inputs!$C$55+K$14+K$18+N39 | X39: =Inputs!$C$6*Inputs!$C$45*Inputs!$C$55+L$14+L$18+N39 | Y39: =Inputs!$C$6*Inputs!$C$46*Inputs!$C$55+M$14+M$18+N39 | Z39: =Inputs!$C$6*Inputs!$C$46*Inputs!$C$55+N$14+N$18 | AA39: =Calendar!M13*Inputs!$C$6+Calendar!E13*Inputs!$C$6+Calendar!Q13*Inputs!$C$112+Inputs!$C$6*Inputs!$C$106/12+Inputs!$C$108*Inputs!$C$107/12 | AB39: =Calendar!M13*Inputs!$C$6*Inputs!$C$101+Calendar!N13*Inputs!$C$6+Calendar!O13*Inputs!$C$113+Calendar!E13*Inputs!$C$6+Calendar!Q13*Inputs!$C$19*Inputs!$C$111+L39 | AC39: =B39*O39+C39*P39+D39*Q39+E39*R39+F39*S39+G39*T39+AA39 | AD39: =B39*U39+C39*V39+D39*W39+E39*X39+F39*Y39+G39*Z39+AB39 | AE39: =B39*MAX(0,O39-Inputs!$C$26)+C39*MAX(0,P39-Inputs!$C$26)+D39*MAX(0,Q39-Inputs!$C$26)+E39*MAX(0,R39-Inputs!$C$26)+F39*MAX(0,S39-Inputs!$C$26)+G39*MAX(0,T39-Inputs!$C$26)+AA39 | AF39: =B39*MAX(0,U39-Inputs!$C$27)+C39*MAX(0,V39-Inputs!$C$27)+D39*MAX(0,W39-Inputs!$C$27)+E39*MAX(0,X39-Inputs!$C$27)+F39*MAX(0,Y39-Inputs!$C$27)+G39*MAX(0,Z39-Inputs!$C$27)+AB39 | AG39: =Inputs!$C$6*Inputs!$C$42*Inputs!$C$47*Inputs!$C$56*B39+(Inputs!$C$6*Inputs!$C$43*Inputs!$C$47*Inputs!$C$56+'Usage Model'!$B$23*Inputs!$C$92)*C39+Inputs!$C$6*Inputs!$C$44*Inputs!$C$48*Inputs!$C$56*D39+Inputs!$C$6*Inputs!$C$45*Inputs!$C$48*Inputs!$C$56*E39+Inputs!$C$6*Inputs!$C$46*Inputs!$C$48*Inputs!$C$56*(F39+G39)+'Usage Model'!$B$24*Inputs!$C$96*B39 | AH39: =Inputs!$C$18*Inputs!$C$15*(B39+C39*Inputs!$C$76) | AI39: =AI38+AH39*Inputs!$C$118/1048576+('Usage Model'!$B$26*(B39+C39)*0.5+'Usage Model'!$B$25*(B39+C39))/1048576+'Usage Model'!$B$23*C39*Inputs!$C$119/1048576+0.05 | AJ39: ='Usage Model'!$B$24*B39*Inputs!$C$97/1024+(Calendar!M13+Calendar!P13)*Inputs!$C$6*Inputs!$C$117/1048576+L39*3/1024 | AK39: =AK38+AJ39 | AL39: =(Inputs!$C$6*Inputs!$C$116*Inputs!$C$115/1024)*(B39+C39)/(Calendar!$B$16+Calendar!$C$16)+'Usage Model'!$B$24*B39*Inputs!$C$97/1024+(Calendar!M13+Calendar!P13)*Inputs!$C$6*Inputs!$C$117/1048576*2 | AM39: =Inputs!$C$14*Inputs!$C$120*Inputs!$C$121/1024+(Inputs!$C$6*Inputs!$C$123+Inputs!$C$7)*Inputs!$C$122*30/1048576 | AN39: =MAX(O39:T39)
A40: =Calendar!A14 | B40: =Calendar!B14 | C40: =Calendar!C14 | D40: =Calendar!D14 | E40: =Calendar!E14 | F40: =Calendar!F14 | G40: =Calendar!G14 | H40: =Calendar!H14 | I40: =Calendar!J14 | J40: =Inputs!$C$50*I40 | K40: =Inputs!$C$98*Calendar!K14 | L40: =Inputs!$C$20*Calendar!L14 | M40: =IF(H40>0,(K40*Inputs!$C$99+L40*Inputs!$C$109)/H40,0) | N40: =IF(H40>0,(K40*Inputs!$C$100+L40*Inputs!$C$110)/H40,0) | O40: =Inputs!$C$6*Inputs!$C$42*(Inputs!$C$47*(Inputs!$C$49+J40)+Inputs!$C$51)+B$14+B$18+M40 | P40: =Inputs!$C$6*Inputs!$C$43*(Inputs!$C$47*(Inputs!$C$49+J40)+Inputs!$C$51)+C$14+C$18+M40 | Q40: =Inputs!$C$6*Inputs!$C$44*(Inputs!$C$48*(Inputs!$C$49+J40)+Inputs!$C$52)+D$14+D$18+M40 | R40: =Inputs!$C$6*Inputs!$C$45*(Inputs!$C$48*(Inputs!$C$49+J40)+Inputs!$C$53)+E$14+E$18+M40 | S40: =Inputs!$C$6*Inputs!$C$46*(Inputs!$C$48*(Inputs!$C$49+J40)+Inputs!$C$53)+F$14+F$18+M40 | T40: =Inputs!$C$6*Inputs!$C$46*(Inputs!$C$48*(Inputs!$C$49+J40)+Inputs!$C$53)+G$14+G$18 | U40: =Inputs!$C$6*Inputs!$C$42*Inputs!$C$54+I$14+I$18+N40 | V40: =Inputs!$C$6*Inputs!$C$43*Inputs!$C$54+J$14+J$18+N40 | W40: =Inputs!$C$6*Inputs!$C$44*Inputs!$C$55+K$14+K$18+N40 | X40: =Inputs!$C$6*Inputs!$C$45*Inputs!$C$55+L$14+L$18+N40 | Y40: =Inputs!$C$6*Inputs!$C$46*Inputs!$C$55+M$14+M$18+N40 | Z40: =Inputs!$C$6*Inputs!$C$46*Inputs!$C$55+N$14+N$18 | AA40: =Calendar!M14*Inputs!$C$6+Calendar!E14*Inputs!$C$6+Calendar!Q14*Inputs!$C$112+Inputs!$C$6*Inputs!$C$106/12+Inputs!$C$108*Inputs!$C$107/12 | AB40: =Calendar!M14*Inputs!$C$6*Inputs!$C$101+Calendar!N14*Inputs!$C$6+Calendar!O14*Inputs!$C$113+Calendar!E14*Inputs!$C$6+Calendar!Q14*Inputs!$C$19*Inputs!$C$111+L40 | AC40: =B40*O40+C40*P40+D40*Q40+E40*R40+F40*S40+G40*T40+AA40 | AD40: =B40*U40+C40*V40+D40*W40+E40*X40+F40*Y40+G40*Z40+AB40 | AE40: =B40*MAX(0,O40-Inputs!$C$26)+C40*MAX(0,P40-Inputs!$C$26)+D40*MAX(0,Q40-Inputs!$C$26)+E40*MAX(0,R40-Inputs!$C$26)+F40*MAX(0,S40-Inputs!$C$26)+G40*MAX(0,T40-Inputs!$C$26)+AA40 | AF40: =B40*MAX(0,U40-Inputs!$C$27)+C40*MAX(0,V40-Inputs!$C$27)+D40*MAX(0,W40-Inputs!$C$27)+E40*MAX(0,X40-Inputs!$C$27)+F40*MAX(0,Y40-Inputs!$C$27)+G40*MAX(0,Z40-Inputs!$C$27)+AB40 | AG40: =Inputs!$C$6*Inputs!$C$42*Inputs!$C$47*Inputs!$C$56*B40+(Inputs!$C$6*Inputs!$C$43*Inputs!$C$47*Inputs!$C$56+'Usage Model'!$B$23*Inputs!$C$92)*C40+Inputs!$C$6*Inputs!$C$44*Inputs!$C$48*Inputs!$C$56*D40+Inputs!$C$6*Inputs!$C$45*Inputs!$C$48*Inputs!$C$56*E40+Inputs!$C$6*Inputs!$C$46*Inputs!$C$48*Inputs!$C$56*(F40+G40)+'Usage Model'!$B$24*Inputs!$C$96*B40 | AH40: =Inputs!$C$18*Inputs!$C$15*(B40+C40*Inputs!$C$76) | AI40: =AI39+AH40*Inputs!$C$118/1048576+('Usage Model'!$B$26*(B40+C40)*0.5+'Usage Model'!$B$25*(B40+C40))/1048576+'Usage Model'!$B$23*C40*Inputs!$C$119/1048576+0.05 | AJ40: ='Usage Model'!$B$24*B40*Inputs!$C$97/1024+(Calendar!M14+Calendar!P14)*Inputs!$C$6*Inputs!$C$117/1048576+L40*3/1024 | AK40: =AK39+AJ40 | AL40: =(Inputs!$C$6*Inputs!$C$116*Inputs!$C$115/1024)*(B40+C40)/(Calendar!$B$16+Calendar!$C$16)+'Usage Model'!$B$24*B40*Inputs!$C$97/1024+(Calendar!M14+Calendar!P14)*Inputs!$C$6*Inputs!$C$117/1048576*2 | AM40: =Inputs!$C$14*Inputs!$C$120*Inputs!$C$121/1024+(Inputs!$C$6*Inputs!$C$123+Inputs!$C$7)*Inputs!$C$122*30/1048576 | AN40: =MAX(O40:T40)
